Workbook

Sheet Variables
A1: Guía de variables del Inspector – Patrol Scrap (Unity)
A2: Leyenda: azul = valor inicial de los scripts (constante) · fondo amarillo = columna 'Mi valor', escribe aquí los tuyos. Si la dejas vacía, las fórmulas de la hoja 'Relaciones' usan el valor inicial.
A4: Script | B4: Sección | C4: Variable | D4: Valor inicial | E4: Unidad | F4: Mi valor | G4: Para qué sirve | H4: Si la subes | I4: Si la bajas
A5: SuspensionCoche | B5: Ruedas | C5: Ruedas (lista) | D5: 4 elementos | G5: Una entrada por rueda (FL, FR, BL, BR)
A6: SuspensionCoche | B6: Ruedas | C6: Anclaje | D6: Rueda_XX | G6: Punto de donde sale el SphereCast. Las delanteras giran aquí
A7: SuspensionCoche | B7: Ruedas | C7: Pivote | D7: Pivote | G7: Objeto visual que sube y baja con el resorte
A8: SuspensionCoche | B8: Ruedas | C8: Delantera | D8: Sí en FL y FR | G8: Marca las ruedas que giran con la dirección
A9: SuspensionCoche | B9: Ruedas | C9: Traccion | D9: Sí en las 4 | G9: Marca las ruedas que reciben fuerza del motor (4x4)
A10: SuspensionCoche | B10: Suspensión | C10: Capa Suelo | D10: Suelo | G10: Capa que detecta el SphereCast. Si no está marcada, el coche cae
A11: SuspensionCoche | B11: Suspensión | C11: Longitud Maxima | D11: 0.9 | E11: m | G11: Recorrido total del resorte (desde el anclaje hasta donde llega el cast) | H11: Más recorrido y más exagerado | I11: Toca fondo antes
A12: SuspensionCoche | B12: Suspensión | C12: Radio Rueda | D12: 0.5 | E12: m | G12: Radio de la esfera del cast. Debe coincidir con el neumático real | H12: Si no coincide con el neumático, la rueda se ve hundida o flotando
A13: SuspensionCoche | B13: Suspensión | C13: Rigidez | D13: 25000 | E13: N/m | G13: Fuerza del resorte por metro comprimido | H13: Coche duro | I13: Coche blando, se hunde y se balancea
A14: SuspensionCoche | B14: Suspensión | C14: Amortiguacion | D14: 2500 | E14: N·s/m | G14: Frena el rebote según la velocidad de compresión | H14: Se asienta rápido, sin vida | I14: Rebota varias veces
A15: SuspensionCoche | B15: Tope | C15: Inicio Tope | D15: 0.8 | E15: fracción (0.5-0.95) | G15: A qué fracción del recorrido empieza el 'tope de goma' | H15: El tope actúa más tarde | I15: El tope actúa antes
A16: SuspensionCoche | B16: Tope | C16: Rigidez Tope | D16: 150000 | E16: N/m | G16: Dureza extra al final del recorrido, para que el cuerpo no toque fondo | H16: Tope más duro | I16: Tope más blando
A17: SuspensionCoche | B17: Depuración | C17: Mostrar Gizmos | D17: No | G17: Dibuja esferas amarillas (recorrido) y rojas (física) en la Scene
A18: EntradaCoche | B18: Entrada | C18: Velocidad Acelerador | D18: 3 | E18: unidades/s | G18: Lo rápido que sube el acelerador de 0 a 1 | H18: Respuesta brusca | I18: Más progresiva
A19: EntradaCoche | B19: Entrada | C19: Velocidad Direccion | D19: 4 | E19: unidades/s | G19: Lo rápido que gira el volante virtual | H19: Giro más nervioso | I19: Más suave
A20: MotorCoche | B20: Motor | C20: Fuerza Motor | D20: 9000 | E20: N | F20: 7000 | G20: Empuje total, repartido entre las ruedas de tracción | H20: Acelera más | I20: Acelera menos
A21: MotorCoche | B21: Motor | C21: Fuerza Freno | D21: 8000 | E21: N | F21: 6000 | G21: Fuerza al pedir lo contrario a lo que haces (vas adelante y pulsas S) | H21: Frena más en seco | I21: Frena más suave
A22: MotorCoche | B22: Motor | C22: Velocidad Maxima | D22: 25 | E22: m/s | F22: 30 | G22: Velocidad a la que el motor deja de empujar (25 m/s = 90 km/h) | H22: Más velocidad punta | I22: Menos velocidad punta
A23: MotorCoche | B23: Motor | C23: Rozamiento | D23: 100 | E23: N por m/s | G23: Resistencia constante, también acelerando | H23: Baja la velocidad máxima real | I23: Menos resistencia
A24: MotorCoche | B24: Motor | C24: Freno Motor | D24: 1500 | E24: N por m/s | G24: Resistencia extra solo al soltar el acelerador | H24: Se detiene antes | I24: Rueda más
A25: MotorCoche | B25: Dirección | C25: Angulo Maximo | D25: 30 | E25: grados | F25: 20 | G25: Giro máximo de las ruedas delanteras | H25: Gira más cerrado | I25: Gira más abierto
A26: MotorCoche | B26: Dirección | C26: Giro A Velocidad Maxima | D26: 0.35 | E26: fracción | G26: Porcentaje de giro disponible a tope de velocidad (0.35 = 35 %) | H26: Más sensible a alta velocidad | I26: Más estable a alta velocidad
A27: MotorCoche | B27: Turbo | C27: Multiplicador Turbo | D27: 1.8 | E27: x | G27: Multiplica la fuerza del motor con turbo | H27: Empuje mayor | I27: Empuje menor
A28: MotorCoche | B28: Turbo | C28: Velocidad Maxima Turbo | D28: 32 | E28: m/s | G28: Nuevo techo de velocidad con turbo | H28: Más velocidad punta con turbo | I28: Menos velocidad punta con turbo
A29: MotorCoche | B29: Turbo | C29: Capacidad Turbo | D29: 100 | E29: unidades | G29: Tamaño del depósito de turbo | H29: Dura más | I29: Dura menos
A30: MotorCoche | B30: Turbo | C30: Consumo Turbo | D30: 25 | E30: unidades/s | G30: Lo que gasta por segundo con el turbo activo | H30: Dura menos | I30: Dura más
A31: MotorCoche | B31: Turbo | C31: Recarga Turbo | D31: 10 | E31: unidades/s | G31: Lo que recupera por segundo si no lo usas | H31: Recarga antes | I31: Recarga más lento
A32: AgarreCoche | B32: Agarre lateral | C32: Rigidez Lateral | D32: 4000 | E32: N por m/s | F32: 6000 | G32: Lo fuerte que frena el deslizamiento lateral | H32: Más agarre (si vibra al ir recto, bájala a 2000-3000) | I32: Más deslizamiento
A33: AgarreCoche | B33: Agarre lateral | C33: Coeficiente Agarre | D33: 1 | F33: 2 | G33: Límite de adherencia: fuerza lateral máxima = peso sobre la rueda × este valor. 1 = asfalto, 0.5 = arena suelta | H33: Más agarre | I33: Derrapa antes
A34: AgarreCoche | B34: Freno de mano | C34: Agarre Trasero Con Freno | D34: 0.35 | E34: fracción (0-1) | G34: Fracción de agarre que conservan las traseras con el freno de mano | H34: Menos derrape | I34: Derrapa más fácil
A35: AgarreCoche | B35: Freno de mano | C35: Frenado Freno Mano | D35: 3000 | E35: N por m/s | G35: Cuánto frena hacia delante el freno de mano | H35: Frena más | I35: Frena menos
A36: EstabilidadCoche | B36: Centro de masa | C36: Centro De Masa | D36: (0, -0.4, 0) | E36: m (local) | G36: Punto de equilibrio del coche, relativo a Patrol | H36: Más alto (Y mayor): vuelca fácil | I36: Más bajo (Y negativa): cuesta más volcar
A37: EstabilidadCoche | B37: Damping rotacional | C37: Damping Yaw | D37: 1.5 | F37: 3 | G37: Freno al giro izquierda/derecha del coche | H37: Deja de rotar antes, pero cuesta girar | I37: Gira más libre
A38: EstabilidadCoche | B38: Damping rotacional | C38: Damping Roll | D38: 4 | G38: Freno al vuelco lateral | H38: Se inclina menos | I38: Se inclina más
A39: EstabilidadCoche | B39: Damping rotacional | C39: Damping Pitch | D39: 4 | G39: Freno al cabeceo (morro arriba/abajo) | H39: Cabecea menos | I39: Cabecea más
A40: EstabilidadCoche | B40: Asistencia | C40: Ayudas Activas | D40: Sí | G40: Activa o desactiva la asistencia de alineación (opción de accesibilidad del GDD)
A41: EstabilidadCoche | B41: Asistencia | C41: Velocidad Minima Asistencia | D41: 5 | E41: m/s | G41: Por debajo de esta velocidad la asistencia no actúa | H41: Actúa solo a más velocidad | I41: Actúa también a poca velocidad
...

Sheet Relaciones
A1: Relaciones útiles (se recalculan con 'Mi valor' o, si está vacío, con el valor inicial)
A3: Datos de entrada (leídos de la hoja Variables)
A4: Dato | B4: Valor | C4: Unidad | D4: Origen
A5: Masa del coche | B5: =IF(Variables!F110="",Variables!D110,Variables!F110) -> 1500 | C5: kg | D5: Hoja Variables: Rigidbody (Patrol) › Mass
A6: Rigidez del resorte | B6: =IF(Variables!F13="",Variables!D13,Variables!F13) -> 25000 | C6: N/m | D6: Hoja Variables: SuspensionCoche › Rigidez
A7: Longitud máxima del resorte | B7: =IF(Variables!F11="",Variables!D11,Variables!F11) -> 0.9 | C7: m | D7: Hoja Variables: SuspensionCoche › Longitud Maxima
A8: Radio de la rueda | B8: =IF(Variables!F12="",Variables!D12,Variables!F12) -> 0.5 | C8: m | D8: Hoja Variables: SuspensionCoche › Radio Rueda
A9: Velocidad máxima | B9: =IF(Variables!F22="",Variables!D22,Variables!F22) -> 30 | C9: m/s | D9: Hoja Variables: MotorCoche › Velocidad Maxima
A10: Capacidad del turbo | B10: =IF(Variables!F29="",Variables!D29,Variables!F29) -> 100 | C10: unidades | D10: Hoja Variables: MotorCoche › Capacidad Turbo
A11: Consumo del turbo (depósito) | B11: =IF(Variables!F30="",Variables!D30,Variables!F30) -> 25 | C11: unidades/s | D11: Hoja Variables: MotorCoche › Consumo Turbo
A12: Recarga del turbo | B12: =IF(Variables!F31="",Variables!D31,Variables!F31) -> 10 | C12: unidades/s | D12: Hoja Variables: MotorCoche › Recarga Turbo
A13: Capacidad de gasolina | B13: =IF(Variables!F92="",Variables!D92,Variables!F92) -> 100 | C13: unidades | D13: Hoja Variables: GasolinaCoche › Capacidad
A14: Consumo ralentí | B14: =IF(Variables!F94="",Variables!D94,Variables!F94) -> 0.1 | C14: unidades/s | D14: Hoja Variables: GasolinaCoche › Consumo Ralenti
A15: Consumo acelerando | B15: =IF(Variables!F95="",Variables!D95,Variables!F95) -> 0.5 | C15: unidades/s | D15: Hoja Variables: GasolinaCoche › Consumo Acelerando
A16: Consumo turbo (gasolina) | B16: =IF(Variables!F96="",Variables!D96,Variables!F96) -> 2 | C16: unidades/s | D16: Hoja Variables: GasolinaCoche › Consumo Turbo
A17: Impacto mínimo que cuesta gasolina | B17: =IF(Variables!F97="",Variables!D97,Variables!F97) -> 6 | C17: m/s | D17: Hoja Variables: GasolinaCoche › Impacto Minimo
A18: Pérdida por impacto | B18: =IF(Variables!F98="",Variables!D98,Variables!F98) -> 0.8 | C18: unidades por m/s | D18: Hoja Variables: GasolinaCoche › Perdida Por Impacto
A19: Factor carrocería | B19: =IF(Variables!F99="",Variables!D99,Variables!F99) -> 1 | C19: x | D19: Hoja Variables: GasolinaCoche › Factor Carroceria
A20: Velocidad mínima de rotura (Destruible) | B20: =IF(Variables!F65="",Variables!D65,Variables!F65) -> 8 | C20: m/s | D20: Hoja Variables: Destruible › Velocidad Minima
A21: Capacidad del maletero | B21: =IF(Variables!F79="",Variables!D79,Variables!F79) -> 20 | C21: unidades | D21: Hoja Variables: InventarioCoche › Capacidad
A22: Distancia de cámara (parado) | B22: =IF(Variables!F45="",Variables!D45,Variables!F45) -> 40 | C22: m | D22: Hoja Variables: CamaraSprung › Distancia Min
A23: Ángulo de elevación de la cámara | B23: =IF(Variables!F47="",Variables!D47,Variables!F47) -> 78 | C23: grados | D23: Hoja Variables: CamaraSprung › Angulo Elevacion
A24: Adelanto de cámara (parado) | B24: =IF(Variables!F48="",Variables!D48,Variables!F48) -> 5 | C24: m | D24: Hoja Variables: CamaraSprung › Adelanto Min
A25: Gravedad | B25: 9.81 | C25: m/s² | D25: Constante física (valor estándar)
A26: Número de ruedas | B26: 4 | C26: ud | D26: Coche de 4 ruedas (supuesto: reparto de peso uniforme)
A27: Velocidad de impacto a probar | B27: 12 | C27: m/s | D27: EDITABLE: ejemplo de choque (12 m/s ≈ 43 km/h) para calcular su coste en gasolina
A29: Suspensión
A30: Resultado | B30: Valor | C30: Unidad | D30: Cómo se calcula
A31: Peso por rueda | B31: =B5*B25/B26 -> 3678.75 | C31: N | D31: masa × gravedad / nº de ruedas
A32: Compresión del resorte en reposo | B32: =B31/B6 -> 0.14715 | C32: m | D32: peso por rueda / rigidez
A33: Alcance máximo del SphereCast | B33: =B8+B7 -> 1.4 | C33: m | D33: radio + longitud máxima (el anclaje debe estar por debajo de esto para tocar suelo)
A34: Altura del anclaje en reposo | B34: =B8+B7-B32 -> 1.25285 | C34: m | D34: radio + longitud máxima − compresión en reposo
A35: Compresión en reposo (% del recorrido) | B35: =B32/B7 -> 0.1635 | C35: % | D35: compresión / longitud máxima
A37: Motor y turbo
A38: Resultado | B38: Valor | C38: Unidad | D38: Cómo se calcula
A39: Velocidad máxima | B39: =B9*3.6 -> 108 | C39: km/h | D39: m/s × 3.6
A40: Duración del depósito de turbo | B40: =B10/B11 -> 4 | C40: s | D40: capacidad / consumo
A41: Recarga completa del depósito de turbo | B41: =B10/B12 -> 10 | C41: s | D41: capacidad / recarga
A43: Gasolina (¿hasta cuándo puedes explorar?)
A44: Resultado | B44: Valor | C44: Unidad | D44: Cómo se calcula
...
